<?xml version="1.0" ?>
<!-- =================================================================================== -->
<!-- |    This document was autogenerated by xacro from sc.xacro                       | -->
<!-- |    EDITING THIS FILE BY HAND IS NOT RECOMMENDED                                 | -->
<!-- =================================================================================== -->
<robot name="SliderCrank">
  <material name="black">
    <color rgba="0.0 0.0 0.0 1.0"/>
  </material>
  <material name="blue">
    <color rgba="0.0 0.0 0.8 1.0"/>
  </material>
  <material name="green">
    <color rgba="0.0 0.8 0.0 1.0"/>
  </material>
  <material name="grey">
    <color rgba="0.2 0.2 0.2 1.0"/>
  </material>
  <material name="orange">
    <color rgba="1.0 0.4235294117647059 0.0392156862745098 1.0"/>
  </material>
  <material name="brown">
    <color rgba="0.8705882352941177 0.8117647058823529 0.7647058823529411 1.0"/>
  </material>
  <material name="red">
    <color rgba="0.8 0.0 0.0 1.0"/>
  </material>
  <material name="white">
    <color rgba="1.0 1.0 1.0 1.0"/>
  </material>
  <!-- ros_control plugin -->
  <gazebo>
    <plugin filename="libgazebo_ros_control.so" name="gazebo_ros_control">
      <robotNamespace>/SliderCrank</robotNamespace>
      <robotSimType>gazebo_ros_control/DefaultRobotHWSim</robotSimType>
    </plugin>
  </gazebo>
  <!-- SC_base -->
  <gazebo reference="SC_base">
    <material>Gazebo/Blue</material>
  </gazebo>
  <!-- SC_link1 -->
  <gazebo reference="SC_link1">
    <mu1>0.2</mu1>
    <mu2>0.2</mu2>
    <material>Gazebo/Red</material>
  </gazebo>
  <!-- SC_link2 -->
  <gazebo reference="SC_link2">
    <mu1>0.2</mu1>
    <mu2>0.2</mu2>
    <material>Gazebo/Red</material>
  </gazebo>
  <!-- SC_Piston -->
  <gazebo reference="SC_Piston">
    <mu1>0.2</mu1>
    <mu2>0.2</mu2>
    <material>Gazebo/Orange</material>
  </gazebo>
  <gazebo>
    <joint name="TRANS01_Base_to_Piston" type="prismatic">
      <child>SC_Piston</child>
      <parent>SC_base</parent>
      <axis>
        <xyz>1 0 0</xyz>
        <limit>
          <lower>-2</lower>
          <upper>2</upper>
        </limit>
        <dynamics>
          <spring_reference>0</spring_reference>
          <spring_stiffness>0</spring_stiffness>
        </dynamics>
        <use_parent_model_frame>1</use_parent_model_frame>
      </axis>
      <origin rpy="0 0 0" xyz="1 0 0.065"/>
    </joint>
  </gazebo>
  <transmission name="tran_REV01_Base_to_Lnik1">
    <type>transmission_interface/SimpleTransmission</type>
    <joint name="REV01_Base_to_Lnik1">
      <hardwareInterface>hardware_interface/EffortJointInterface</hardwareInterface>
    </joint>
    <actuator name="motor_REV01_Base_to_Lnik1">
      <hardwareInterface>hardware_interface/EffortJointInterface</hardwareInterface>
      <mechanicalReduction>1</mechanicalReduction>
    </actuator>
  </transmission>
  <transmission name="tran_REV02_Lnik1_to_Lnik2">
    <type>transmission_interface/SimpleTransmission</type>
    <joint name="REV02_Lnik1_to_Lnik2">
      <hardwareInterface>hardware_interface/EffortJointInterface</hardwareInterface>
    </joint>
    <actuator name="motor_REV02_Lnik1_to_Lnik2">
      <hardwareInterface>hardware_interface/EffortJointInterface</hardwareInterface>
      <mechanicalReduction>1</mechanicalReduction>
    </actuator>
  </transmission>
  <transmission name="tran_REV03_Lnik2_to_Piston">
    <type>transmission_interface/SimpleTransmission</type>
    <joint name="REV03_Lnik2_to_Piston">
      <hardwareInterface>hardware_interface/EffortJointInterface</hardwareInterface>
    </joint>
    <actuator name="motor_REV03_Lnik2_to_Piston">
      <hardwareInterface>hardware_interface/EffortJointInterface</hardwareInterface>
      <mechanicalReduction>1</mechanicalReduction>
    </actuator>
  </transmission>
  <transmission name="tran_TRANS01_Base_to_Piston">
    <type>transmission_interface/SimpleTransmission</type>
    <joint name="TRANS01_Base_to_Piston">
      <hardwareInterface>hardware_interface/EffortJointInterface</hardwareInterface>
    </joint>
    <actuator name="motor_TRANS01_Base_to_Piston">
      <hardwareInterface>hardware_interface/EffortJointInterface</hardwareInterface>
      <mechanicalReduction>1</mechanicalReduction>
    </actuator>
  </transmission>
  <link name="world"/>
  <joint name="fixed" type="fixed">
    <parent link="world"/>
    <child link="SC_base"/>
    <origin rpy="1.5707963267948966 0 1.5707963267948966" xyz="0 0 1.0"/>
  </joint>
  <!-- base -->
  <link name="SC_base">
    <collision>
      <origin rpy="0 0 0" xyz="0 0 0"/>
      <geometry>
        <box size="0.1 0.1 0.1"/>
      </geometry>
    </collision>
    <visual>
      <origin rpy="0 0 0" xyz="0 0 0"/>
      <geometry>
        <box size="0.1 0.1 0.1"/>
        <!-- <mesh filename="package://sc_description/meshes/SC_Base.stl"/> -->
      </geometry>
      <material name="blue"/>
    </visual>
    <inertial>
      <origin rpy="0 0 0" xyz="0 0 0"/>
      <mass value="1"/>
      <inertia ixx="0.001666666666666667" ixy="0.0" ixz="0.0" iyy="0.001666666666666667" iyz="0.0" izz="0.001666666666666667"/>
    </inertial>
  </link>
  <joint name="REV01_Base_to_Lnik1" type="continuous">
    <axis xyz="0 0 1"/>
    <parent link="SC_base"/>
    <child link="SC_link1"/>
    <origin rpy="0 0 -0.5235987755982988" xyz="0 0 0.07500000000000001"/>
    <dynamics damping="0.7"/>
  </joint>
  <!-- link1 -->
  <link name="SC_link1">
    <collision>
      <origin rpy="0 0 0" xyz="0 0.25000000000000006 0"/>
      <geometry>
        <box size="0.05 0.5500000000000002 0.05"/>
      </geometry>
    </collision>
    <visual>
      <!-- <origin rpy="0 0 0" xyz="0 ${cos(60*deg2rad)/2} 0"/> -->
      <origin rpy="0 0 0" xyz="0 0 0"/>
      <geometry>
        <!-- <box size="${link_side} ${link1_length} ${link_side}"/> -->
        <mesh filename="package://sc_description/meshes/SC_link1.stl"/>
      </geometry>
    </visual>
    <inertial>
      <origin rpy="0 0 0" xyz="0 0.25000000000000006 0"/>
      <mass value="1"/>
      <inertia ixx="0.025416666666666678" ixy="0.0" ixz="0.0" iyy="0.00041666666666666675" iyz="0.0" izz="0.025416666666666678"/>
    </inertial>
  </link>
  <joint name="REV02_Lnik1_to_Lnik2" type="continuous">
    <axis xyz="0 0 1"/>
    <parent link="SC_link1"/>
    <child link="SC_link2"/>
    <origin rpy="0 0 -1.5707963267948966" xyz="0 0.5000000000000001 0.05"/>
    <dynamics damping="0.7"/>
  </joint>
  <!-- link2 -->
  <link name="SC_link2">
    <collision>
      <origin rpy="0 0 0" xyz="0 0.4330127018922193 0"/>
      <geometry>
        <box size="0.05 0.9160254037844386 0.05"/>
      </geometry>
    </collision>
    <visual>
      <!-- <origin rpy="0 0 0" xyz="0 ${sin(60*deg2rad)/2} 0"/> -->
      <origin rpy="0 0 0" xyz="0 0 0"/>
      <geometry>
        <!-- <box size="${link_side} ${link2_length} ${link_side}"/> -->
        <mesh filename="package://sc_description/meshes/SC_link2.stl"/>
      </geometry>
    </visual>
    <inertial>
      <origin rpy="0 0 0" xyz="0 0.4330127018922193 0"/>
      <mass value="1"/>
      <inertia ixx="0.07013354503153699" ixy="0.0" ixz="0.0" iyy="0.00041666666666666675" iyz="0.0" izz="0.07013354503153699"/>
    </inertial>
  </link>
  <joint name="REV03_Lnik2_to_Piston" type="continuous">
    <axis xyz="0 0 1"/>
    <parent link="SC_link2"/>
    <child link="SC_Piston"/>
    <origin rpy="0 0 2.0943951023931953" xyz="0 0.8660254037844386 -0.065"/>
    <dynamics damping="0.7"/>
  </joint>
  <!-- piston -->
  <link name="SC_Piston">
    <collision>
      <origin rpy="0 0 0" xyz="0 0 0"/>
      <geometry>
        <box size="0.08000000000000002 0.08000000000000002 0.08000000000000002"/>
      </geometry>
    </collision>
    <visual>
      <geometry>
        <box size="0.08000000000000002 0.08000000000000002 0.08000000000000002"/>
        <!-- <mesh filename="package://sc_description/meshes/SC_Pis.stl"/> -->
      </geometry>
      <origin rpy="0 0 0" xyz="0 0 0"/>
    </visual>
    <inertial>
      <origin rpy="0 0 0" xyz="0 0 0"/>
      <mass value="1"/>
      <inertia ixx="0.0010666666666666672" ixy="0.0" ixz="0.0" iyy="0.0010666666666666672" iyz="0.0" izz="0.0010666666666666672"/>
    </inertial>
  </link>
  <!-- <joint name="TRANS01_Base_to_Piston" type="prismatic">
    <axis xyz="1 0 0"/>
    <parent link="SC_base"/>
    <child link="SC_Piston"/>
    <limit effort="1000.0" lower="-2" upper="2" velocity="0.5"/>
    <origin rpy="0 0 0" xyz="1 0 ${piston_side/2+link_side/2}"/>
    <dynamics damping="0.7"/>
  </joint> -->
</robot>

